Workbook

Sheet Raw Order Data
A1: Order ID | B1: Order Date | C1: Ship Date | D1: Warehouse | E1: Country | F1: Carrier | G1: Units Ordered | H1: Units Shipped
A2: ORD-0001 | B2: 46239 | C2: 46240 | D2: Fidelity NL | E2: Germany | F2: FedEx | G2: 2 | H2: 2
A3: ORD-0002 | B3: 46241 | C3: 46242 | D3: Devlnd UK | E3: United Kingdom | F3: DPD | G3: 3 | H3: 3
A4: ORD-0003 | B4: 46244 | C4: 46246 | D4: InterFulfillment CA | E4: Canada | F4: UPS | G4: 4 | H4: 4
A5: ORD-0004 | B5: 46245 | C5: 46247 | D5: Fidelity NL | E5: Germany | F5: Royal Mail | G5: 6 | H5: 6
A6: ORD-0005 | B6: 46247 | C6: 46250 | D6: Devlnd UK | E6: United Kingdom | F6: DHL | G6: 12 | H6: 12
A7: ORD-0006 | B7: 46251 | C7: 46255 | D7: InterFulfillment CA | E7: Canada | F7: FedEx | G7: 1 | H7: 1
A8: ORD-0007 | B8: 46251 | C8: 46256 | D8: Fidelity NL | E8: Germany | F8: DPD | G8: 2 | H8: 1
A9: ORD-0008 | B9: 46253 | C9: 46260 | D9: Devlnd UK | E9: United Kingdom | F9: UPS | G9: 3 | H9: 3
A10: ORD-0009 | B10: 46255 | C10: 46255 | D10: InterFulfillment CA | E10: Canada | F10: Royal Mail | G10: 4 | H10: 4
A11: ORD-0010 | B11: 46258 | C11: 46259 | D11: Fidelity NL | E11: Germany | F11: DHL | G11: 6 | H11: 6
A12: ORD-0011 | B12: 46259 | D12: Devlnd UK | E12: United Kingdom | F12: FedEx | G12: 12 | H12: 12
A13: ORD-0012 | B13: 46261 | C13: 46263 | D13: InterFulfillment CA | E13: Canada | F13: DPD | G13: 1 | H13: 1
A14: ORD-0013 | B14: 46265 | C14: 46267 | D14: Fidelity NL | E14: Germany | F14: UPS | G14: 2 | H14: 2
A15: ORD-0014 | B15: 46265 | C15: 46268 | D15: Devlnd UK | E15: United Kingdom | F15: Royal Mail | G15: 3 | H15: 3
A16: ORD-0015 | B16: 46238 | C16: 46242 | D16: InterFulfillment CA | E16: Canada | F16: DHL | G16: 4 | H16: 4
A17: ORD-0016 | B17: 46240 | C17: 46245 | D17: Fidelity NL | E17: Germany | F17: FedEx | G17: 6 | H17: 6
A18: ORD-0017 | B18: 46244 | C18: 46251 | D18: Devlnd UK | E18: United Kingdom | F18: DPD | G18: 12 | H18: 12
A19: ORD-0018 | B19: 46244 | C19: 46244 | D19: InterFulfillment CA | E19: Canada | F19: UPS | G19: 1 | H19: 1
A20: ORD-0019 | B20: 46246 | C20: 46247 | D20: Fidelity NL | E20: Germany | F20: Royal Mail | G20: 2 | H20: 1
A21: ORD-0020 | B21: 46248 | C21: 46249 | D21: Devlnd UK | E21: United Kingdom | F21: DHL | G21: 3 | H21: 3
A22: ORD-0021 | B22: 46251 | C22: 46253 | D22: InterFulfillment CA | E22: Canada | F22: FedEx | G22: 4 | H22: 4
A23: ORD-0022 | B23: 46252 | C23: 46254 | D23: Fidelity NL | E23: Germany | F23: DPD | G23: 6 | H23: 6
A24: ORD-0023 | B24: 46254 | C24: 46257 | D24: Devlnd UK | E24: United Kingdom | F24: UPS | G24: 12 | H24: 12
... A27: ORD-0026 | B27: 46260 | C27: 46267 | D27: Devlnd UK | E27: United Kingdom | F27: FedEx | G27: 3 | H27: 3
A28: ORD-0027 | B28: 46262 | D28: InterFulfillment CA | E28: Canada | F28: DPD | G28: 4 | H28: 4
A29: ORD-0028 | B29: 46265 | C29: 46266 | D29: Fidelity NL | E29: Germany | F29: UPS | G29: 6 | H29: 6
A30: ORD-0029 | B30: 46237 | C30: 46238 | D30: Devlnd UK | E30: United Kingdom | F30: Royal Mail | G30: 12 | H30: 12
A31: ORD-0030 | B31: 46239 | C31: 46241 | D31: InterFulfillment CA | E31: Canada | F31: DHL | G31: 1 | H31: 1
A32: ORD-0031 | B32: 46241 | C32: 46243 | D32: Fidelity NL | E32: Germany | F32: FedEx | G32: 2 | H32: 2
A33: ORD-0032 | B33: 46244 | C33: 46247 | D33: Devlnd UK | E33: United Kingdom | F33: DPD | G33: 3 | H33: 3
A34: ORD-0033 | B34: 46245 | C34: 46249 | D34: InterFulfillment CA | E34: Canada | F34: UPS | G34: 4 | H34: 4
A35: ORD-0034 | B35: 46247 | C35: 46252 | D35: Fidelity NL | E35: Germany | F35: Royal Mail | G35: 6 | H35: 5
A36: ORD-0035 | B36: 46251 | C36: 46258 | D36: Devlnd UK | E36: United Kingdom | F36: DHL | G36: 12 | H36: 12
A37: ORD-0036 | B37: 46251 | C37: 46251 | D37: InterFulfillment CA | E37: Canada | F37: FedEx | G37: 1 | H37: 1
A38: ORD-0037 | B38: 46253 | C38: 46254 | D38: Fidelity NL | E38: Germany | F38: DPD | G38: 2 | H38: 2
A39: ORD-0038 | B39: 46255 | C39: 46256 | D39: Devlnd UK | E39: United Kingdom | F39: UPS | G39: 3 | H39: 3
A40: ORD-0039 | B40: 46258 | C40: 46260 | D40: InterFulfillment CA | E40: Canada | F40: Royal Mail | G40: 4 | H40: 4
... A43: ORD-0042 | B43: 46265 | C43: 46269 | D43: InterFulfillment CA | E43: Canada | F43: DPD | G43: 1 | H43: 1
A44: ORD-0043 | B44: 46265 | D44: Fidelity NL | E44: Germany | F44: UPS | G44: 2 | H44: 2
...

Sheet Inbound Data
A1: Inbound PO | B1: Expected Inbound Units | C1: Received Inbound Units | D1: Issue Flag | E1: Operational Notes
A2: PO-DE-1005 | B2: 100 | C2: 100 | E2: Inbound received within expected quantity.
A3: PO-FI-1022 | B3: 100 | C3: 96 | D3: Inbound discrepancy | E3: Pallet count matches, but unit count does not match the packing list.
A4: PO-IN-1039 | B4: 100 | C4: 100 | E4: Inbound received within expected quantity.
A5: PO-DE-1056 | B5: 100 | C5: 96 | D5: Inbound discrepancy | E5: Pallet count matches, but unit count does not match the packing list.

Sheet Instructions
A1: Candidate Workbook Instructions
A3: Use the Raw Order Data tab for fulfillment SLA analysis and the Inbound Data tab for warehouse and forwarder reconciliation. Do not overwrite the raw data.
A4: Create your analysis in new tabs or columns. Use formulas where practical so the calculations can be audited.
A6: Assumptions for this exercise
A7: Order-processing SLA: orders should ship within 2 business days of the order date.
A8: Business days exclude Saturdays and Sundays. No holidays need to be excluded.
A9: For orders with no ship date, do not invent a ship date. Flag them for follow-up.
A10: For inbound discrepancies, compare Expected Inbound Units with Received Inbound Units on the Inbound Data tab.
A12: Expected outputs
A13: 1. Row-level business-day ship time and SLA status.
A14: 2. Summary by warehouse and carrier, including average ship time, order volume, over-SLA orders, and percentage over SLA.
A15: 3. Reconciliation summary for any inbound or short-shipment discrepancies.
A16: 4. A short list of operational priorities and recommended next actions.

Sheet SLA Analysis
A1: Order ID | B1: Order Date | C1: Ship Date | D1: Warehouse | E1: Country | F1: Carrier | G1: Units Ordered | H1: Units Shipped | I1: Business Days to Ship | J1: SLA Status | K1: Over SLA Flag | L1: Shipping Status | M1: Unit Variance | N1: Shipment Completeness
A2: ORD-0001 | B2: 46239 | C2: 46240 | D2: Fidelity NL | E2: Germany | F2: FedEx | G2: 2 | H2: 2 | I2: =IF(C2="","",MAX(0,NETWORKDAYS(B2,C2)-1)) -> 1 | J2: =IF(C2="","Missing Ship Date",IF(I2>2,"Over SLA","Within SLA")) -> Within SLA | K2: =IF(J2="Over SLA",1,0) -> 0 | L2: =IF(C2="","Missing Ship Date","Ship Date Recorded") -> Ship Date Recorded | M2: =IF(OR(G2="",H2=""),"",H2-G2) -> 0 | N2: =IF(OR(G2="",H2=""),"Pending Verification",IF(C2="","Shipping Date Missing",IF(M2<0,"Short Shipment",IF(M2>0,"Over Shipment","Complete")))) -> Complete
A3: ORD-0002 | B3: 46241 | C3: 46242 | D3: Devlnd UK | E3: United Kingdom | F3: DPD | G3: 3 | H3: 3 | I3: =IF(C3="","",MAX(0,NETWORKDAYS(B3,C3)-1)) -> 0 | J3: =IF(C3="","Missing Ship Date",IF(I3>2,"Over SLA","Within SLA")) -> Within SLA | K3: =IF(J3="Over SLA",1,0) -> 0 | L3: =IF(C3="","Missing Ship Date","Ship Date Recorded") -> Ship Date Recorded | M3: =IF(OR(G3="",H3=""),"",H3-G3) -> 0 | N3: =IF(OR(G3="",H3=""),"Pending Verification",IF(C3="","Shipping Date Missing",IF(M3<0,"Short Shipment",IF(M3>0,"Over Shipment","Complete")))) -> Complete
A4: ORD-0003 | B4: 46244 | C4: 46246 | D4: InterFulfillment CA | E4: Canada | F4: UPS | G4: 4 | H4: 4 | I4: =IF(C4="","",MAX(0,NETWORKDAYS(B4,C4)-1)) -> 2 | J4: =IF(C4="","Missing Ship Date",IF(I4>2,"Over SLA","Within SLA")) -> Within SLA | K4: =IF(J4="Over SLA",1,0) -> 0 | L4: =IF(C4="","Missing Ship Date","Ship Date Recorded") -> Ship Date Recorded | M4: =IF(OR(G4="",H4=""),"",H4-G4) -> 0 | N4: =IF(OR(G4="",H4=""),"Pending Verification",IF(C4="","Shipping Date Missing",IF(M4<0,"Short Shipment",IF(M4>0,"Over Shipment","Complete")))) -> Complete
A5: ORD-0004 | B5: 46245 | C5: 46247 | D5: Fidelity NL | E5: Germany | F5: Royal Mail | G5: 6 | H5: 6 | I5: =IF(C5="","",MAX(0,NETWORKDAYS(B5,C5)-1)) -> 2 | J5: =IF(C5="","Missing Ship Date",IF(I5>2,"Over SLA","Within SLA")) -> Within SLA | K5: =IF(J5="Over SLA",1,0) -> 0 | L5: =IF(C5="","Missing Ship Date","Ship Date Recorded") -> Ship Date Recorded | M5: =IF(OR(G5="",H5=""),"",H5-G5) -> 0 | N5: =IF(OR(G5="",H5=""),"Pending Verification",IF(C5="","Shipping Date Missing",IF(M5<0,"Short Shipment",IF(M5>0,"Over Shipment","Complete")))) -> Complete
A6: ORD-0005 | B6: 46247 | C6: 46250 | D6: Devlnd UK | E6: United Kingdom | F6: DHL | G6: 12 | H6: 12 | I6: =IF(C6="","",MAX(0,NETWORKDAYS(B6,C6)-1)) -> 1 | J6: =IF(C6="","Missing Ship Date",IF(I6>2,"Over SLA","Within SLA")) -> Within SLA | K6: =IF(J6="Over SLA",1,0) -> 0 | L6: =IF(C6="","Missing Ship Date","Ship Date Recorded") -> Ship Date Recorded | M6: =IF(OR(G6="",H6=""),"",H6-G6) -> 0 | N6: =IF(OR(G6="",H6=""),"Pending Verification",IF(C6="","Shipping Date Missing",IF(M6<0,"Short Shipment",IF(M6>0,"Over Shipment","Complete")))) -> Complete
A7: ORD-0006 | B7: 46251 | C7: 46255 | D7: InterFulfillment CA | E7: Canada | F7: FedEx | G7: 1 | H7: 1 | I7: =IF(C7="","",MAX(0,NETWORKDAYS(B7,C7)-1)) -> 4 | J7: =IF(C7="","Missing Ship Date",IF(I7>2,"Over SLA","Within SLA")) -> Over SLA | K7: =IF(J7="Over SLA",1,0) -> 1 | L7: =IF(C7="","Missing Ship Date","Ship Date Recorded") -> Ship Date Recorded | M7: =IF(OR(G7="",H7=""),"",H7-G7) -> 0 | N7: =IF(OR(G7="",H7=""),"Pending Verification",IF(C7="","Shipping Date Missing",IF(M7<0,"Short Shipment",IF(M7>0,"Over Shipment","Complete")))) -> Complete
A8: ORD-0007 | B8: 46251 | C8: 46256 | D8: Fidelity NL | E8: Germany | F8: DPD | G8: 2 | H8: 1 | I8: =IF(C8="","",MAX(0,NETWORKDAYS(B8,C8)-1)) -> 4 | J8: =IF(C8="","Missing Ship Date",IF(I8>2,"Over SLA","Within SLA")) -> Over SLA | K8: =IF(J8="Over SLA",1,0) -> 1 | L8: =IF(C8="","Missing Ship Date","Ship Date Recorded") -> Ship Date Recorded | M8: =IF(OR(G8="",H8=""),"",H8-G8) -> -1 | N8: =IF(OR(G8="",H8=""),"Pending Verification",IF(C8="","Shipping Date Missing",IF(M8<0,"Short Shipment",IF(M8>0,"Over Shipment","Complete")))) -> Short Shipment
A9: ORD-0008 | B9: 46253 | C9: 46260 | D9: Devlnd UK | E9: United Kingdom | F9: UPS | G9: 3 | H9: 3 | I9: =IF(C9="","",MAX(0,NETWORKDAYS(B9,C9)-1)) -> 5 | J9: =IF(C9="","Missing Ship Date",IF(I9>2,"Over SLA","Within SLA")) -> Over SLA | K9: =IF(J9="Over SLA",1,0) -> 1 | L9: =IF(C9="","Missing Ship Date","Ship Date Recorded") -> Ship Date Recorded | M9: =IF(OR(G9="",H9=""),"",H9-G9) -> 0 | N9: =IF(OR(G9="",H9=""),"Pending Verification",IF(C9="","Shipping Date Missing",IF(M9<0,"Short Shipment",IF(M9>0,"Over Shipment","Complete")))) -> Complete
A10: ORD-0009 | B10: 46255 | C10: 46255 | D10: InterFulfillment CA | E10: Canada | F10: Royal Mail | G10: 4 | H10: 4 | I10: =IF(C10="","",MAX(0,NETWORKDAYS(B10,C10)-1)) -> 0 | J10: =IF(C10="","Missing Ship Date",IF(I10>2,"Over SLA","Within SLA")) -> Within SLA | K10: =IF(J10="Over SLA",1,0) -> 0 | L10: =IF(C10="","Missing Ship Date","Ship Date Recorded") -> Ship Date Recorded | M10: =IF(OR(G10="",H10=""),"",H10-G10) -> 0 | N10: =IF(OR(G10="",H10=""),"Pending Verification",IF(C10="","Shipping Date Missing",IF(M10<0,"Short Shipment",IF(M10>0,"Over Shipment","Complete")))) -> Complete
A11: ORD-0010 | B11: 46258 | C11: 46259 | D11: Fidelity NL | E11: Germany | F11: DHL | G11: 6 | H11: 6 | I11: =IF(C11="","",MAX(0,NETWORKDAYS(B11,C11)-1)) -> 1 | J11: =IF(C11="","Missing Ship Date",IF(I11>2,"Over SLA","Within SLA")) -> Within SLA | K11: =IF(J11="Over SLA",1,0) -> 0 | L11: =IF(C11="","Missing Ship Date","Ship Date Recorded") -> Ship Date Recorded | M11: =IF(OR(G11="",H11=""),"",H11-G11) -> 0 | N11: =IF(OR(G11="",H11=""),"Pending Verification",IF(C11="","Shipping Date Missing",IF(M11<0,"Short Shipment",IF(M11>0,"Over Shipment","Complete")))) -> Complete
A12: ORD-0011 | B12: 46259 | D12: Devlnd UK | E12: United Kingdom | F12: FedEx | G12: 12 | H12: 12 | I12: =IF(C12="","",MAX(0,NETWORKDAYS(B12,C12)-1)) | J12: =IF(C12="","Missing Ship Date",IF(I12>2,"Over SLA","Within SLA")) -> Missing Ship Date | K12: =IF(J12="Over SLA",1,0) -> 0 | L12: =IF(C12="","Missing Ship Date","Ship Date Recorded") -> Missing Ship Date | M12: =IF(OR(G12="",H12=""),"",H12-G12) -> 0 | N12: =IF(OR(G12="",H12=""),"Pending Verification",IF(C12="","Shipping Date Missing",IF(M12<0,"Short Shipment",IF(M12>0,"Over Shipment","Complete")))) -> Shipping Date Missing
A13: ORD-0012 | B13: 46261 | C13: 46263 | D13: InterFulfillment CA | E13: Canada | F13: DPD | G13: 1 | H13: 1 | I13: =IF(C13="","",MAX(0,NETWORKDAYS(B13,C13)-1)) -> 1 | J13: =IF(C13="","Missing Ship Date",IF(I13>2,"Over SLA","Within SLA")) -> Within SLA | K13: =IF(J13="Over SLA",1,0) -> 0 | L13: =IF(C13="","Missing Ship Date","Ship Date Recorded") -> Ship Date Recorded | M13: =IF(OR(G13="",H13=""),"",H13-G13) -> 0 | N13: =IF(OR(G13="",H13=""),"Pending Verification",IF(C13="","Shipping Date Missing",IF(M13<0,"Short Shipment",IF(M13>0,"Over Shipment","Complete")))) -> Complete
A14: ORD-0013 | B14: 46265 | C14: 46267 | D14: Fidelity NL | E14: Germany | F14: UPS | G14: 2 | H14: 2 | I14: =IF(C14="","",MAX(0,NETWORKDAYS(B14,C14)-1)) -> 2 | J14: =IF(C14="","Missing Ship Date",IF(I14>2,"Over SLA","Within SLA")) -> Within SLA | K14: =IF(J14="Over SLA",1,0) -> 0 | L14: =IF(C14="","Missing Ship Date","Ship Date Recorded") -> Ship Date Recorded | M14: =IF(OR(G14="",H14=""),"",H14-G14) -> 0 | N14: =IF(OR(G14="",H14=""),"Pending Verification",IF(C14="","Shipping Date Missing",IF(M14<0,"Short Shipment",IF(M14>0,"Over Shipment","Complete")))) -> Complete
A15: ORD-0014 | B15: 46265 | C15: 46268 | D15: Devlnd UK | E15: United Kingdom | F15: Royal Mail | G15: 3 | H15: 3 | I15: =IF(C15="","",MAX(0,NETWORKDAYS(B15,C15)-1)) -> 3 | J15: =IF(C15="","Missing Ship Date",IF(I15>2,"Over SLA","Within SLA")) -> Over SLA | K15: =IF(J15="Over SLA",1,0) -> 1 | L15: =IF(C15="","Missing Ship Date","Ship Date Recorded") -> Ship Date Recorded | M15: =IF(OR(G15="",H15=""),"",H15-G15) -> 0 | N15: =IF(OR(G15="",H15=""),"Pending Verification",IF(C15="","Shipping Date Missing",IF(M15<0,"Short Shipment",IF(M15>0,"Over Shipment","Complete")))) -> Complete
A16: ORD-0015 | B16: 46238 | C16: 46242 | D16: InterFulfillment CA | E16: Canada | F16: DHL | G16: 4 | H16: 4 | I16: =IF(C16="","",MAX(0,NETWORKDAYS(B16,C16)-1)) -> 3 | J16: =IF(C16="","Missing Ship Date",IF(I16>2,"Over SLA","Within SLA")) -> Over SLA | K16: =IF(J16="Over SLA",1,0) -> 1 | L16: =IF(C16="","Missing Ship Date","Ship Date Recorded") -> Ship Date Recorded | M16: =IF(OR(G16="",H16=""),"",H16-G16) -> 0 | N16: =IF(OR(G16="",H16=""),"Pending Verification",IF(C16="","Shipping Date Missing",IF(M16<0,"Short Shipment",IF(M16>0,"Over Shipment","Complete")))) -> Complete
A17: ORD-0016 | B17: 46240 | C17: 46245 | D17: Fidelity NL | E17: Germany | F17: FedEx | G17: 6 | H17: 6 | I17: =IF(C17="","",MAX(0,NETWORKDAYS(B17,C17)-1)) -> 3 | J17: =IF(C17="","Missing Ship Date",IF(I17>2,"Over SLA","Within SLA")) -> Over SLA | K17: =IF(J17="Over SLA",1,0) -> 1 | L17: =IF(C17="","Missing Ship Date","Ship Date Recorded") -> Ship Date Recorded | M17: =IF(OR(G17="",H17=""),"",H17-G17) -> 0 | N17: =IF(OR(G17="",H17=""),"Pending Verification",IF(C17="","Shipping Date Missing",IF(M17<0,"Short Shipment",IF(M17>0,"Over Shipment","Complete")))) -> Complete
A18: ORD-0017 | B18: 46244 | C18: 46251 | D18: Devlnd UK | E18: United Kingdom | F18: DPD | G18: 12 | H18: 12 | I18: =IF(C18="","",MAX(0,NETWORKDAYS(B18,C18)-1)) -> 5 | J18: =IF(C18="","Missing Ship Date",IF(I18>2,"Over SLA","Within SLA")) -> Over SLA | K18: =IF(J18="Over SLA",1,0) -> 1 | L18: =IF(C18="","Missing Ship Date","Ship Date Recorded") -> Ship Date Recorded | M18: =IF(OR(G18="",H18=""),"",H18-G18) -> 0 | N18: =IF(OR(G18="",H18=""),"Pending Verification",IF(C18="","Shipping Date Missing",IF(M18<0,"Short Shipment",IF(M18>0,"Over Shipment","Complete")))) -> Complete
A19: ORD-0018 | B19: 46244 | C19: 46244 | D19: InterFulfillment CA | E19: Canada | F19: UPS | G19: 1 | H19: 1 | I19: =IF(C19="","",MAX(0,NETWORKDAYS(B19,C19)-1)) -> 0 | J19: =IF(C19="","Missing Ship Date",IF(I19>2,"Over SLA","Within SLA")) -> Within SLA | K19: =IF(J19="Over SLA",1,0) -> 0 | L19: =IF(C19="","Missing Ship Date","Ship Date Recorded") -> Ship Date Recorded | M19: =IF(OR(G19="",H19=""),"",H19-G19) -> 0 | N19: =IF(OR(G19="",H19=""),"Pending Verification",IF(C19="","Shipping Date Missing",IF(M19<0,"Short Shipment",IF(M19>0,"Over Shipment","Complete")))) -> Complete
A20: ORD-0019 | B20: 46246 | C20: 46247 | D20: Fidelity NL | E20: Germany | F20: Royal Mail | G20: 2 | H20: 1 | I20: =IF(C20="","",MAX(0,NETWORKDAYS(B20,C20)-1)) -> 1 | J20: =IF(C20="","Missing Ship Date",IF(I20>2,"Over SLA","Within SLA")) -> Within SLA | K20: =IF(J20="Over SLA",1,0) -> 0 | L20: =IF(C20="","Missing Ship Date","Ship Date Recorded") -> Ship Date Recorded | M20: =IF(OR(G20="",H20=""),"",H20-G20) -> -1 | N20: =IF(OR(G20="",H20=""),"Pending Verification",IF(C20="","Shipping Date Missing",IF(M20<0,"Short Shipment",IF(M20>0,"Over Shipment","Complete")))) -> Short Shipment
A21: ORD-0020 | B21: 46248 | C21: 46249 | D21: Devlnd UK | E21: United Kingdom | F21: DHL | G21: 3 | H21: 3 | I21: =IF(C21="","",MAX(0,NETWORKDAYS(B21,C21)-1)) -> 0 | J21: =IF(C21="","Missing Ship Date",IF(I21>2,"Over SLA","Within SLA")) -> Within SLA | K21: =IF(J21="Over SLA",1,0) -> 0 | L21: =IF(C21="","Missing Ship Date","Ship Date Recorded") -> Ship Date Recorded | M21: =IF(OR(G21="",H21=""),"",H21-G21) -> 0 | N21: =IF(OR(G21="",H21=""),"Pending Verification",IF(C21="","Shipping Date Missing",IF(M21<0,"Short Shipment",IF(M21>0,"Over Shipment","Complete")))) -> Complete
A22: ORD-0021 | B22: 46251 | C22: 46253 | D22: InterFulfillment CA | E22: Canada | F22: FedEx | G22: 4 | H22: 4 | I22: =IF(C22="","",MAX(0,NETWORKDAYS(B22,C22)-1)) -> 2 | J22: =IF(C22="","Missing Ship Date",IF(I22>2,"Over SLA","Within SLA")) -> Within SLA | K22: =IF(J22="Over SLA",1,0) -> 0 | L22: =IF(C22="","Missing Ship Date","Ship Date Recorded") -> Ship Date Recorded | M22: =IF(OR(G22="",H22=""),"",H22-G22) -> 0 | N22: =IF(OR(G22="",H22=""),"Pending Verification",IF(C22="","Shipping Date Missing",IF(M22<0,"Short Shipment",IF(M22>0,"Over Shipment","Complete")))) -> Complete
A23: ORD-0022 | B23: 46252 | C23: 46254 | D23: Fidelity NL | E23: Germany | F23: DPD | G23: 6 | H23: 6 | I23: =IF(C23="","",MAX(0,NETWORKDAYS(B23,C23)-1)) -> 2 | J23: =IF(C23="","Missing Ship Date",IF(I23>2,"Over SLA","Within SLA")) -> Within SLA | K23: =IF(J23="Over SLA",1,0) -> 0 | L23: =IF(C23="","Missing Ship Date","Ship Date Recorded") -> Ship Date Recorded | M23: =IF(OR(G23="",H23=""),"",H23-G23) -> 0 | N23: =IF(OR(G23="",H23=""),"Pending Verification",IF(C23="","Shipping Date Missing",IF(M23<0,"Short Shipment",IF(M23>0,"Over Shipment","Complete")))) -> Complete
A24: ORD-0023 | B24: 46254 | C24: 46257 | D24: Devlnd UK | E24: United Kingdom | F24: UPS | G24: 12 | H24: 12 | I24: =IF(C24="","",MAX(0,NETWORKDAYS(B24,C24)-1)) -> 1 | J24: =IF(C24="","Missing Ship Date",IF(I24>2,"Over SLA","Within SLA")) -> Within SLA | K24: =IF(J24="Over SLA",1,0) -> 0 | L24: =IF(C24="","Missing Ship Date","Ship Date Recorded") -> Ship Date Recorded | M24: =IF(OR(G24="",H24=""),"",H24-G24) -> 0 | N24: =IF(OR(G24="",H24=""),"Pending Verification",IF(C24="","Shipping Date Missing",IF(M24<0,"Short Shipment",IF(M24>0,"Over Shipment","Complete")))) -> Complete
... A27: ORD-0026 | B27: 46260 | C27: 46267 | D27: Devlnd UK | E27: United Kingdom | F27: FedEx | G27: 3 | H27: 3 | I27: =IF(C27="","",MAX(0,NETWORKDAYS(B27,C27)-1)) -> 5 | J27: =IF(C27="","Missing Ship Date",IF(I27>2,"Over SLA","Within SLA")) -> Over SLA | K27: =IF(J27="Over SLA",1,0) -> 1 | L27: =IF(C27="","Missing Ship Date","Ship Date Recorded") -> Ship Date Recorded | M27: =IF(OR(G27="",H27=""),"",H27-G27) -> 0 | N27: =IF(OR(G27="",H27=""),"Pending Verification",IF(C27="","Shipping Date Missing",IF(M27<0,"Short Shipment",IF(M27>0,"Over Shipment","Complete")))) -> Complete
A28: ORD-0027 | B28: 46262 | D28: InterFulfillment CA | E28: Canada | F28: DPD | G28: 4 | H28: 4 | I28: =IF(C28="","",MAX(0,NETWORKDAYS(B28,C28)-1)) | J28: =IF(C28="","Missing Ship Date",IF(I28>2,"Over SLA","Within SLA")) -> Missing Ship Date | K28: =IF(J28="Over SLA",1,0) -> 0 | L28: =IF(C28="","Missing Ship Date","Ship Date Recorded") -> Missing Ship Date | M28: =IF(OR(G28="",H28=""),"",H28-G28) -> 0 | N28: =IF(OR(G28="",H28=""),"Pending Verification",IF(C28="","Shipping Date Missing",IF(M28<0,"Short Shipment",IF(M28>0,"Over Shipment","Complete")))) -> Shipping Date Missing
A29: ORD-0028 | B29: 46265 | C29: 46266 | D29: Fidelity NL | E29: Germany | F29: UPS | G29: 6 | H29: 6 | I29: =IF(C29="","",MAX(0,NETWORKDAYS(B29,C29)-1)) -> 1 | J29: =IF(C29="","Missing Ship Date",IF(I29>2,"Over SLA","Within SLA")) -> Within SLA | K29: =IF(J29="Over SLA",1,0) -> 0 | L29: =IF(C29="","Missing Ship Date","Ship Date Recorded") -> Ship Date Recorded | M29: =IF(OR(G29="",H29=""),"",H29-G29) -> 0 | N29: =IF(OR(G29="",H29=""),"Pending Verification",IF(C29="","Shipping Date Missing",IF(M29<0,"Short Shipment",IF(M29>0,"Over Shipment","Complete")))) -> Complete
A30: ORD-0029 | B30: 46237 | C30: 46238 | D30: Devlnd UK | E30: United Kingdom | F30: Royal Mail | G30: 12 | H30: 12 | I30: =IF(C30="","",MAX(0,NETWORKDAYS(B30,C30)-1)) -> 1 | J30: =IF(C30="","Missing Ship Date",IF(I30>2,"Over SLA","Within SLA")) -> Within SLA | K30: =IF(J30="Over SLA",1,0) -> 0 | L30: =IF(C30="","Missing Ship Date","Ship Date Recorded") -> Ship Date Recorded | M30: =IF(OR(G30="",H30=""),"",H30-G30) -> 0 | N30: =IF(OR(G30="",H30=""),"Pending Verification",IF(C30="","Shipping Date Missing",IF(M30<0,"Short Shipment",IF(M30>0,"Over Shipment","Complete")))) -> Complete
A31: ORD-0030 | B31: 46239 | C31: 46241 | D31: InterFulfillment CA | E31: Canada | F31: DHL | G31: 1 | H31: 1 | I31: =IF(C31="","",MAX(0,NETWORKDAYS(B31,C31)-1)) -> 2 | J31: =IF(C31="","Missing Ship Date",IF(I31>2,"Over SLA","Within SLA")) -> Within SLA | K31: =IF(J31="Over SLA",1,0) -> 0 | L31: =IF(C31="","Missing Ship Date","Ship Date Recorded") -> Ship Date Recorded | M31: =IF(OR(G31="",H31=""),"",H31-G31) -> 0 | N31: =IF(OR(G31="",H31=""),"Pending Verification",IF(C31="","Shipping Date Missing",IF(M31<0,"Short Shipment",IF(M31>0,"Over Shipment","Complete")))) -> Complete
A32: ORD-0031 | B32: 46241 | C32: 46243 | D32: Fidelity NL | E32: Germany | F32: FedEx | G32: 2 | H32: 2 | I32: =IF(C32="","",MAX(0,NETWORKDAYS(B32,C32)-1)) -> 0 | J32: =IF(C32="","Missing Ship Date",IF(I32>2,"Over SLA","Within SLA")) -> Within SLA | K32: =IF(J32="Over SLA",1,0) -> 0 | L32: =IF(C32="","Missing Ship Date","Ship Date Recorded") -> Ship Date Recorded | M32: =IF(OR(G32="",H32=""),"",H32-G32) -> 0 | N32: =IF(OR(G32="",H32=""),"Pending Verification",IF(C32="","Shipping Date Missing",IF(M32<0,"Short Shipment",IF(M32>0,"Over Shipment","Complete")))) -> Complete
A33: ORD-0032 | B33: 46244 | C33: 46247 | D33: Devlnd UK | E33: United Kingdom | F33: DPD | G33: 3 | H33: 3 | I33: =IF(C33="","",MAX(0,NETWORKDAYS(B33,C33)-1)) -> 3 | J33: =IF(C33="","Missing Ship Date",IF(I33>2,"Over SLA","Within SLA")) -> Over SLA | K33: =IF(J33="Over SLA",1,0) -> 1 | L33: =IF(C33="","Missing Ship Date","Ship Date Recorded") -> Ship Date Recorded | M33: =IF(OR(G33="",H33=""),"",H33-G33) -> 0 | N33: =IF(OR(G33="",H33=""),"Pending Verification",IF(C33="","Shipping Date Missing",IF(M33<0,"Short Shipment",IF(M33>0,"Over Shipment","Complete")))) -> Complete
A34: ORD-0033 | B34: 46245 | C34: 46249 | D34: InterFulfillment CA | E34: Canada | F34: UPS | G34: 4 | H34: 4 | I34: =IF(C34="","",MAX(0,NETWORKDAYS(B34,C34)-1)) -> 3 | J34: =IF(C34="","Missing Ship Date",IF(I34>2,"Over SLA","Within SLA")) -> Over SLA | K34: =IF(J34="Over SLA",1,0) -> 1 | L34: =IF(C34="","Missing Ship Date","Ship Date Recorded") -> Ship Date Recorded | M34: =IF(OR(G34="",H34=""),"",H34-G34) -> 0 | N34: =IF(OR(G34="",H34=""),"Pending Verification",IF(C34="","Shipping Date Missing",IF(M34<0,"Short Shipment",IF(M34>0,"Over Shipment","Complete")))) -> Complete
A35: ORD-0034 | B35: 46247 | C35: 46252 | D35: Fidelity NL | E35: Germany | F35: Royal Mail | G35: 6 | H35: 5 | I35: =IF(C35="","",MAX(0,NETWORKDAYS(B35,C35)-1)) -> 3 | J35: =IF(C35="","Missing Ship Date",IF(I35>2,"Over SLA","Within SLA")) -> Over SLA | K35: =IF(J35="Over SLA",1,0) -> 1 | L35: =IF(C35="","Missing Ship Date","Ship Date Recorded") -> Ship Date Recorded | M35: =IF(OR(G35="",H35=""),"",H35-G35) -> -1 | N35: =IF(OR(G35="",H35=""),"Pending Verification",IF(C35="","Shipping Date Missing",IF(M35<0,"Short Shipment",IF(M35>0,"Over Shipment","Complete")))) -> Short Shipment
A36: ORD-0035 | B36: 46251 | C36: 46258 | D36: Devlnd UK | E36: United Kingdom | F36: DHL | G36: 12 | H36: 12 | I36: =IF(C36="","",MAX(0,NETWORKDAYS(B36,C36)-1)) -> 5 | J36: =IF(C36="","Missing Ship Date",IF(I36>2,"Over SLA","Within SLA")) -> Over SLA | K36: =IF(J36="Over SLA",1,0) -> 1 | L36: =IF(C36="","Missing Ship Date","Ship Date Recorded") -> Ship Date Recorded | M36: =IF(OR(G36="",H36=""),"",H36-G36) -> 0 | N36: =IF(OR(G36="",H36=""),"Pending Verification",IF(C36="","Shipping Date Missing",IF(M36<0,"Short Shipment",IF(M36>0,"Over Shipment","Complete")))) -> Complete
A37: ORD-0036 | B37: 46251 | C37: 46251 | D37: InterFulfillment CA | E37: Canada | F37: FedEx | G37: 1 | H37: 1 | I37: =IF(C37="","",MAX(0,NETWORKDAYS(B37,C37)-1)) -> 0 | J37: =IF(C37="","Missing Ship Date",IF(I37>2,"Over SLA","Within SLA")) -> Within SLA | K37: =IF(J37="Over SLA",1,0) -> 0 | L37: =IF(C37="","Missing Ship Date","Ship Date Recorded") -> Ship Date Recorded | M37: =IF(OR(G37="",H37=""),"",H37-G37) -> 0 | N37: =IF(OR(G37="",H37=""),"Pending Verification",IF(C37="","Shipping Date Missing",IF(M37<0,"Short Shipment",IF(M37>0,"Over Shipment","Complete")))) -> Complete
A38: ORD-0037 | B38: 46253 | C38: 46254 | D38: Fidelity NL | E38: Germany | F38: DPD | G38: 2 | H38: 2 | I38: =IF(C38="","",MAX(0,NETWORKDAYS(B38,C38)-1)) -> 1 | J38: =IF(C38="","Missing Ship Date",IF(I38>2,"Over SLA","Within SLA")) -> Within SLA | K38: =IF(J38="Over SLA",1,0) -> 0 | L38: =IF(C38="","Missing Ship Date","Ship Date Recorded") -> Ship Date Recorded | M38: =IF(OR(G38="",H38=""),"",H38-G38) -> 0 | N38: =IF(OR(G38="",H38=""),"Pending Verification",IF(C38="","Shipping Date Missing",IF(M38<0,"Short Shipment",IF(M38>0,"Over Shipment","Complete")))) -> Complete
A39: ORD-0038 | B39: 46255 | C39: 46256 | D39: Devlnd UK | E39: United Kingdom | F39: UPS | G39: 3 | H39: 3 | I39: =IF(C39="","",MAX(0,NETWORKDAYS(B39,C39)-1)) -> 0 | J39: =IF(C39="","Missing Ship Date",IF(I39>2,"Over SLA","Within SLA")) -> Within SLA | K39: =IF(J39="Over SLA",1,0) -> 0 | L39: =IF(C39="","Missing Ship Date","Ship Date Recorded") -> Ship Date Recorded | M39: =IF(OR(G39="",H39=""),"",H39-G39) -> 0 | N39: =IF(OR(G39="",H39=""),"Pending Verification",IF(C39="","Shipping Date Missing",IF(M39<0,"Short Shipment",IF(M39>0,"Over Shipment","Complete")))) -> Complete
A40: ORD-0039 | B40: 46258 | C40: 46260 | D40: InterFulfillment CA | E40: Canada | F40: Royal Mail | G40: 4 | H40: 4 | I40: =IF(C40="","",MAX(0,NETWORKDAYS(B40,C40)-1)) -> 2 | J40: =IF(C40="","Missing Ship Date",IF(I40>2,"Over SLA","Within SLA")) -> Within SLA | K40: =IF(J40="Over SLA",1,0) -> 0 | L40: =IF(C40="","Missing Ship Date","Ship Date Recorded") -> Ship Date Recorded | M40: =IF(OR(G40="",H40=""),"",H40-G40) -> 0 | N40: =IF(OR(G40="",H40=""),"Pending Verification",IF(C40="","Shipping Date Missing",IF(M40<0,"Short Shipment",IF(M40>0,"Over Shipment","Complete")))) -> Complete
... A43: ORD-0042 | B43: 46265 | C43: 46269 | D43: InterFulfillment CA | E43: Canada | F43: DPD | G43: 1 | H43: 1 | I43: =IF(C43="","",MAX(0,NETWORKDAYS(B43,C43)-1)) -> 4 | J43: =IF(C43="","Missing Ship Date",IF(I43>2,"Over SLA","Within SLA")) -> Over SLA | K43: =IF(J43="Over SLA",1,0) -> 1 | L43: =IF(C43="","Missing Ship Date","Ship Date Recorded") -> Ship Date Recorded | M43: =IF(OR(G43="",H43=""),"",H43-G43) -> 0 | N43: =IF(OR(G43="",H43=""),"Pending Verification",IF(C43="","Shipping Date Missing",IF(M43<0,"Short Shipment",IF(M43>0,"Over Shipment","Complete")))) -> Complete
A44: ORD-0043 | B44: 46265 | D44: Fidelity NL | E44: Germany | F44: UPS | G44: 2 | H44: 2 | I44: =IF(C44="","",MAX(0,NETWORKDAYS(B44,C44)-1)) | J44: =IF(C44="","Missing Ship Date",IF(I44>2,"Over SLA","Within SLA")) -> Missing Ship Date | K44: =IF(J44="Over SLA",1,0) -> 0 | L44: =IF(C44="","Missing Ship Date","Ship Date Recorded") -> Missing Ship Date | M44: =IF(OR(G44="",H44=""),"",H44-G44) -> 0 | N44: =IF(OR(G44="",H44=""),"Pending Verification",IF(C44="","Shipping Date Missing",IF(M44<0,"Short Shipment",IF(M44>0,"Over Shipment","Complete")))) -> Shipping Date Missing
...

Sheet Performance Summary
A1: Warehouse | B1: Carrier | C1: Total Orders | D1: Shipped Orders | E1: Avg. Business Days | F1: Over SLA Orders | G1: Over SLA % | H1: Missing Ship Date Orders | J1: Warehouse | K1: Total Orders | L1: Shipped Orders | M1: Over SLA Orders | N1: Over SLA % | O1: Not Shipped Orders | P1: Avg. Business Days
A2: {=UNIQUE({'SLA Analysis'!D2:D61,'SLA Analysis'!F2:F61})} -> Fidelity NL | B2: FedEx | C2: =COUNTIFS('SLA Analysis'!D$2:D$61,A2,'SLA Analysis'!F$2:F$61,B2) -> 4 | D2: =COUNTIFS('SLA Analysis'!D$2:D$61,A2,'SLA Analysis'!F$2:F$61,B2,'SLA Analysis'!C$2:C$61,"<>") -> 4 | E2: =IFERROR(AVERAGEIFS('SLA Analysis'!I$2:I$61,'SLA Analysis'!D$2:D$61,A2,'SLA Analysis'!F$2:F$61,B2),"") -> 1.25 | F2: =COUNTIFS('SLA Analysis'!D$2:D$61,A2,'SLA Analysis'!F$2:F$61,B2,'SLA Analysis'!J$2:J$61,"Over SLA") -> 1 | G2: =IFERROR(F2/D2,0) -> 0.25 | H2: =COUNTIFS('SLA Analysis'!D$2:D$61,A2,'SLA Analysis'!F$2:F$61,B2,'SLA Analysis'!C$2:C$61,"") -> 0 | J2: {=UNIQUE(A2:A16)} -> Fidelity NL | K2: =SUMIF($A$2:$A$16,J2,$C$2:$C$16) -> 20 | L2: =SUMIF($A$2:$A$16,J2,$D$2:$D$16) -> 19 | M2: =SUMIF($A$2:$A$16,J2,$F$2:$F$16) -> 5 | N2: =IFERROR(M2/L2,0) -> 0.26315789 | O2: =SUMIF($A$2:$A$16,J2,$H$2:$H$16) -> 1 | P2: =IFERROR(AVERAGEIF('SLA Analysis'!$D$2:$D$61,J2,'SLA Analysis'!$I$2:$I$61),0) -> 1.7894737
A3: Devlnd UK | B3: DPD | C3: =COUNTIFS('SLA Analysis'!D$2:D$61,A3,'SLA Analysis'!F$2:F$61,B3) -> 4 | D3: =COUNTIFS('SLA Analysis'!D$2:D$61,A3,'SLA Analysis'!F$2:F$61,B3,'SLA Analysis'!C$2:C$61,"<>") -> 4 | E3: =IFERROR(AVERAGEIFS('SLA Analysis'!I$2:I$61,'SLA Analysis'!D$2:D$61,A3,'SLA Analysis'!F$2:F$61,B3),"") -> 2.25 | F3: =COUNTIFS('SLA Analysis'!D$2:D$61,A3,'SLA Analysis'!F$2:F$61,B3,'SLA Analysis'!J$2:J$61,"Over SLA") -> 2 | G3: =IFERROR(F3/D3,0) -> 0.5 | H3: =COUNTIFS('SLA Analysis'!D$2:D$61,A3,'SLA Analysis'!F$2:F$61,B3,'SLA Analysis'!C$2:C$61,"") -> 0 | J3: Devlnd UK | K3: =SUMIF($A$2:$A$16,J3,$C$2:$C$16) -> 20 | L3: =SUMIF($A$2:$A$16,J3,$D$2:$D$16) -> 19 | M3: =SUMIF($A$2:$A$16,J3,$F$2:$F$16) -> 9 | N3: =IFERROR(M3/L3,0) -> 0.47368421 | O3: =SUMIF($A$2:$A$16,J3,$H$2:$H$16) -> 1 | P3: =IFERROR(AVERAGEIF('SLA Analysis'!$D$2:$D$61,J3,'SLA Analysis'!$I$2:$I$61),0) -> 2.4210526
A4: InterFulfillment CA | B4: UPS | C4: =COUNTIFS('SLA Analysis'!D$2:D$61,A4,'SLA Analysis'!F$2:F$61,B4) -> 4 | D4: =COUNTIFS('SLA Analysis'!D$2:D$61,A4,'SLA Analysis'!F$2:F$61,B4,'SLA Analysis'!C$2:C$61,"<>") -> 4 | E4: =IFERROR(AVERAGEIFS('SLA Analysis'!I$2:I$61,'SLA Analysis'!D$2:D$61,A4,'SLA Analysis'!F$2:F$61,B4),"") -> 1.75 | F4: =COUNTIFS('SLA Analysis'!D$2:D$61,A4,'SLA Analysis'!F$2:F$61,B4,'SLA Analysis'!J$2:J$61,"Over SLA") -> 1 | G4: =IFERROR(F4/D4,0) -> 0.25 | H4: =COUNTIFS('SLA Analysis'!D$2:D$61,A4,'SLA Analysis'!F$2:F$61,B4,'SLA Analysis'!C$2:C$61,"") -> 0 | J4: InterFulfillment CA | K4: =SUMIF($A$2:$A$16,J4,$C$2:$C$16) -> 20 | L4: =SUMIF($A$2:$A$16,J4,$D$2:$D$16) -> 19 | M4: =SUMIF($A$2:$A$16,J4,$F$2:$F$16) -> 6 | N4: =IFERROR(M4/L4,0) -> 0.31578947 | O4: =SUMIF($A$2:$A$16,J4,$H$2:$H$16) -> 1 | P4: =IFERROR(AVERAGEIF('SLA Analysis'!$D$2:$D$61,J4,'SLA Analysis'!$I$2:$I$61),0) -> 1.8947368
A5: Fidelity NL | B5: Royal Mail | C5: =COUNTIFS('SLA Analysis'!D$2:D$61,A5,'SLA Analysis'!F$2:F$61,B5) -> 4 | D5: =COUNTIFS('SLA Analysis'!D$2:D$61,A5,'SLA Analysis'!F$2:F$61,B5,'SLA Analysis'!C$2:C$61,"<>") -> 4 | E5: =IFERROR(AVERAGEIFS('SLA Analysis'!I$2:I$61,'SLA Analysis'!D$2:D$61,A5,'SLA Analysis'!F$2:F$61,B5),"") -> 1.5 | F5: =COUNTIFS('SLA Analysis'!D$2:D$61,A5,'SLA Analysis'!F$2:F$61,B5,'SLA Analysis'!J$2:J$61,"Over SLA") -> 1 | G5: =IFERROR(F5/D5,0) -> 0.25 | H5: =COUNTIFS('SLA Analysis'!D$2:D$61,A5,'SLA Analysis'!F$2:F$61,B5,'SLA Analysis'!C$2:C$61,"") -> 0
A6: Devlnd UK | B6: DHL | C6: =COUNTIFS('SLA Analysis'!D$2:D$61,A6,'SLA Analysis'!F$2:F$61,B6) -> 4 | D6: =COUNTIFS('SLA Analysis'!D$2:D$61,A6,'SLA Analysis'!F$2:F$61,B6,'SLA Analysis'!C$2:C$61,"<>") -> 4 | E6: =IFERROR(AVERAGEIFS('SLA Analysis'!I$2:I$61,'SLA Analysis'!D$2:D$61,A6,'SLA Analysis'!F$2:F$61,B6),"") -> 2.25 | F6: =COUNTIFS('SLA Analysis'!D$2:D$61,A6,'SLA Analysis'!F$2:F$61,B6,'SLA Analysis'!J$2:J$61,"Over SLA") -> 2 | G6: =IFERROR(F6/D6,0) -> 0.5 | H6: =COUNTIFS('SLA Analysis'!D$2:D$61,A6,'SLA Analysis'!F$2:F$61,B6,'SLA Analysis'!C$2:C$61,"") -> 0
A7: InterFulfillment CA | B7: FedEx | C7: =COUNTIFS('SLA Analysis'!D$2:D$61,A7,'SLA Analysis'!F$2:F$61,B7) -> 4 | D7: =COUNTIFS('SLA Analysis'!D$2:D$61,A7,'SLA Analysis'!F$2:F$61,B7,'SLA Analysis'!C$2:C$61,"<>") -> 4 | E7: =IFERROR(AVERAGEIFS('SLA Analysis'!I$2:I$61,'SLA Analysis'!D$2:D$61,A7,'SLA Analysis'!F$2:F$61,B7),"") -> 2.25 | F7: =COUNTIFS('SLA Analysis'!D$2:D$61,A7,'SLA Analysis'!F$2:F$61,B7,'SLA Analysis'!J$2:J$61,"Over SLA") -> 2 | G7: =IFERROR(F7/D7,0) -> 0.5 | H7: =COUNTIFS('SLA Analysis'!D$2:D$61,A7,'SLA Analysis'!F$2:F$61,B7,'SLA Analysis'!C$2:C$61,"") -> 0
A8: Fidelity NL | B8: DPD | C8: =COUNTIFS('SLA Analysis'!D$2:D$61,A8,'SLA Analysis'!F$2:F$61,B8) -> 4 | D8: =COUNTIFS('SLA Analysis'!D$2:D$61,A8,'SLA Analysis'!F$2:F$61,B8,'SLA Analysis'!C$2:C$61,"<>") -> 4 | E8: =IFERROR(AVERAGEIFS('SLA Analysis'!I$2:I$61,'SLA Analysis'!D$2:D$61,A8,'SLA Analysis'!F$2:F$61,B8),"") -> 2.5 | F8: =COUNTIFS('SLA Analysis'!D$2:D$61,A8,'SLA Analysis'!F$2:F$61,B8,'SLA Analysis'!J$2:J$61,"Over SLA") -> 2 | G8: =IFERROR(F8/D8,0) -> 0.5 | H8: =COUNTIFS('SLA Analysis'!D$2:D$61,A8,'SLA Analysis'!F$2:F$61,B8,'SLA Analysis'!C$2:C$61,"") -> 0
A9: Devlnd UK | B9: UPS | C9: =COUNTIFS('SLA Analysis'!D$2:D$61,A9,'SLA Analysis'!F$2:F$61,B9) -> 4 | D9: =COUNTIFS('SLA Analysis'!D$2:D$61,A9,'SLA Analysis'!F$2:F$61,B9,'SLA Analysis'!C$2:C$61,"<>") -> 4 | E9: =IFERROR(AVERAGEIFS('SLA Analysis'!I$2:I$61,'SLA Analysis'!D$2:D$61,A9,'SLA Analysis'!F$2:F$61,B9),"") -> 2.75 | F9: =COUNTIFS('SLA Analysis'!D$2:D$61,A9,'SLA Analysis'!F$2:F$61,B9,'SLA Analysis'!J$2:J$61,"Over SLA") -> 2 | G9: =IFERROR(F9/D9,0) -> 0.5 | H9: =COUNTIFS('SLA Analysis'!D$2:D$61,A9,'SLA Analysis'!F$2:F$61,B9,'SLA Analysis'!C$2:C$61,"") -> 0
A10: InterFulfillment CA | B10: Royal Mail | C10: =COUNTIFS('SLA Analysis'!D$2:D$61,A10,'SLA Analysis'!F$2:F$61,B10) -> 4 | D10: =COUNTIFS('SLA Analysis'!D$2:D$61,A10,'SLA Analysis'!F$2:F$61,B10,'SLA Analysis'!C$2:C$61,"<>") -> 4 | E10: =IFERROR(AVERAGEIFS('SLA Analysis'!I$2:I$61,'SLA Analysis'!D$2:D$61,A10,'SLA Analysis'!F$2:F$61,B10),"") -> 1.5 | F10: =COUNTIFS('SLA Analysis'!D$2:D$61,A10,'SLA Analysis'!F$2:F$61,B10,'SLA Analysis'!J$2:J$61,"Over SLA") -> 1 | G10: =IFERROR(F10/D10,0) -> 0.25 | H10: =COUNTIFS('SLA Analysis'!D$2:D$61,A10,'SLA Analysis'!F$2:F$61,B10,'SLA Analysis'!C$2:C$61,"") -> 0
A11: Fidelity NL | B11: DHL | C11: =COUNTIFS('SLA Analysis'!D$2:D$61,A11,'SLA Analysis'!F$2:F$61,B11) -> 4 | D11: =COUNTIFS('SLA Analysis'!D$2:D$61,A11,'SLA Analysis'!F$2:F$61,B11,'SLA Analysis'!C$2:C$61,"<>") -> 4 | E11: =IFERROR(AVERAGEIFS('SLA Analysis'!I$2:I$61,'SLA Analysis'!D$2:D$61,A11,'SLA Analysis'!F$2:F$61,B11),"") -> 2 | F11: =COUNTIFS('SLA Analysis'!D$2:D$61,A11,'SLA Analysis'!F$2:F$61,B11,'SLA Analysis'!J$2:J$61,"Over SLA") -> 1 | G11: =IFERROR(F11/D11,0) -> 0.25 | H11: =COUNTIFS('SLA Analysis'!D$2:D$61,A11,'SLA Analysis'!F$2:F$61,B11,'SLA Analysis'!C$2:C$61,"") -> 0
A12: Devlnd UK | B12: FedEx | C12: =COUNTIFS('SLA Analysis'!D$2:D$61,A12,'SLA Analysis'!F$2:F$61,B12) -> 4 | D12: =COUNTIFS('SLA Analysis'!D$2:D$61,A12,'SLA Analysis'!F$2:F$61,B12,'SLA Analysis'!C$2:C$61,"<>") -> 3 | E12: =IFERROR(AVERAGEIFS('SLA Analysis'!I$2:I$61,'SLA Analysis'!D$2:D$61,A12,'SLA Analysis'!F$2:F$61,B12),"") -> 2 | F12: =COUNTIFS('SLA Analysis'!D$2:D$61,A12,'SLA Analysis'!F$2:F$61,B12,'SLA Analysis'!J$2:J$61,"Over SLA") -> 1 | G12: =IFERROR(F12/D12,0) -> 0.33333333 | H12: =COUNTIFS('SLA Analysis'!D$2:D$61,A12,'SLA Analysis'!F$2:F$61,B12,'SLA Analysis'!C$2:C$61,"") -> 1
A13: InterFulfillment CA | B13: DPD | C13: =COUNTIFS('SLA Analysis'!D$2:D$61,A13,'SLA Analysis'!F$2:F$61,B13) -> 4 | D13: =COUNTIFS('SLA Analysis'!D$2:D$61,A13,'SLA Analysis'!F$2:F$61,B13,'SLA Analysis'!C$2:C$61,"<>") -> 3 | E13: =IFERROR(AVERAGEIFS('SLA Analysis'!I$2:I$61,'SLA Analysis'!D$2:D$61,A13,'SLA Analysis'!F$2:F$61,B13),"") -> 2.3333333 | F13: =COUNTIFS('SLA Analysis'!D$2:D$61,A13,'SLA Analysis'!F$2:F$61,B13,'SLA Analysis'!J$2:J$61,"Over SLA") -> 1 | G13: =IFERROR(F13/D13,0) -> 0.33333333 | H13: =COUNTIFS('SLA Analysis'!D$2:D$61,A13,'SLA Analysis'!F$2:F$61,B13,'SLA Analysis'!C$2:C$61,"") -> 1
A14: Fidelity NL | B14: UPS | C14: =COUNTIFS('SLA Analysis'!D$2:D$61,A14,'SLA Analysis'!F$2:F$61,B14) -> 4 | D14: =COUNTIFS('SLA Analysis'!D$2:D$61,A14,'SLA Analysis'!F$2:F$61,B14,'SLA Analysis'!C$2:C$61,"<>") -> 3 | E14: =IFERROR(AVERAGEIFS('SLA Analysis'!I$2:I$61,'SLA Analysis'!D$2:D$61,A14,'SLA Analysis'!F$2:F$61,B14),"") -> 1.6666667 | F14: =COUNTIFS('SLA Analysis'!D$2:D$61,A14,'SLA Analysis'!F$2:F$61,B14,'SLA Analysis'!J$2:J$61,"Over SLA") -> 0 | G14: =IFERROR(F14/D14,0) -> 0 | H14: =COUNTIFS('SLA Analysis'!D$2:D$61,A14,'SLA Analysis'!F$2:F$61,B14,'SLA Analysis'!C$2:C$61,"") -> 1
A15: Devlnd UK | B15: Royal Mail | C15: =COUNTIFS('SLA Analysis'!D$2:D$61,A15,'SLA Analysis'!F$2:F$61,B15) -> 4 | D15: =COUNTIFS('SLA Analysis'!D$2:D$61,A15,'SLA Analysis'!F$2:F$61,B15,'SLA Analysis'!C$2:C$61,"<>") -> 4 | E15: =IFERROR(AVERAGEIFS('SLA Analysis'!I$2:I$61,'SLA Analysis'!D$2:D$61,A15,'SLA Analysis'!F$2:F$61,B15),"") -> 2.75 | F15: =COUNTIFS('SLA Analysis'!D$2:D$61,A15,'SLA Analysis'!F$2:F$61,B15,'SLA Analysis'!J$2:J$61,"Over SLA") -> 2 | G15: =IFERROR(F15/D15,0) -> 0.5 | H15: =COUNTIFS('SLA Analysis'!D$2:D$61,A15,'SLA Analysis'!F$2:F$61,B15,'SLA Analysis'!C$2:C$61,"") -> 0
A16: InterFulfillment CA | B16: DHL | C16: =COUNTIFS('SLA Analysis'!D$2:D$61,A16,'SLA Analysis'!F$2:F$61,B16) -> 4 | D16: =COUNTIFS('SLA Analysis'!D$2:D$61,A16,'SLA Analysis'!F$2:F$61,B16,'SLA Analysis'!C$2:C$61,"<>") -> 4 | E16: =IFERROR(AVERAGEIFS('SLA Analysis'!I$2:I$61,'SLA Analysis'!D$2:D$61,A16,'SLA Analysis'!F$2:F$61,B16),"") -> 1.75 | F16: =COUNTIFS('SLA Analysis'!D$2:D$61,A16,'SLA Analysis'!F$2:F$61,B16,'SLA Analysis'!J$2:J$61,"Over SLA") -> 1 | G16: =IFERROR(F16/D16,0) -> 0.25 | H16: =COUNTIFS('SLA Analysis'!D$2:D$61,A16,'SLA Analysis'!F$2:F$61,B16,'SLA Analysis'!C$2:C$61,"") -> 0

Sheet Inbound Reconciliation
A1: Inbound PO | B1: Expected Inbound Units | C1: Received Inbound Units | D1: Issue Flag | E1: Operational Notes | F1: Unit Variance | G1: Classification | H1: Missing Units | I1: Investigation Required | J1: Recommended Action | L1: Inbound PO | M1: Expected | N1: Received | T1: Total Inbound POs
A2: PO-DE-1005 | B2: 100 | C2: 100 | E2: Inbound received within expected quantity. | F2: =IF(OR(B2="",C2=""),"",C2-B2) -> 0 | G2: =IF(F2="","Pending Verification",IF(F2=0,"Matched",IF(F2<0,"Short Received","Over Received"))) -> Matched | H2: =IF(F2="","",MAX(0,-F2)) -> 0 | I2: =IF(G2="Matched","No","Yes") -> No | J2: =IF(G2="Matched","No action required",IF(G2="Short Received","Hold PO closure - investigate shortage",IF(G2="Over Received","Investigate excess receipt","Verify missing data"))) -> No action required | L2: =A2 -> PO-DE-1005 | M2: =B2 -> 100 | N2: =C2 -> 100
A3: PO-FI-1022 | B3: 100 | C3: 96 | D3: Inbound discrepancy | E3: Pallet count matches, but unit count does not match the packing list. | F3: =IF(OR(B3="",C3=""),"",C3-B3) -> -4 | G3: =IF(F3="","Pending Verification",IF(F3=0,"Matched",IF(F3<0,"Short Received","Over Received"))) -> Short Received | H3: =IF(F3="","",MAX(0,-F3)) -> 4 | I3: =IF(G3="Matched","No","Yes") -> Yes | J3: =IF(G3="Matched","No action required",IF(G3="Short Received","Hold PO closure - investigate shortage",IF(G3="Over Received","Investigate excess receipt","Verify missing data"))) -> Hold PO closure - investigate shortage | L3: =A3 -> PO-FI-1022 | M3: =B3 -> 100 | N3: =C3 -> 96 | T3: =COUNTA(A2:A5) -> 4
A4: PO-IN-1039 | B4: 100 | C4: 100 | E4: Inbound received within expected quantity. | F4: =IF(OR(B4="",C4=""),"",C4-B4) -> 0 | G4: =IF(F4="","Pending Verification",IF(F4=0,"Matched",IF(F4<0,"Short Received","Over Received"))) -> Matched | H4: =IF(F4="","",MAX(0,-F4)) -> 0 | I4: =IF(G4="Matched","No","Yes") -> No | J4: =IF(G4="Matched","No action required",IF(G4="Short Received","Hold PO closure - investigate shortage",IF(G4="Over Received","Investigate excess receipt","Verify missing data"))) -> No action required | L4: =A4 -> PO-IN-1039 | M4: =B4 -> 100 | N4: =C4 -> 100
A5: PO-DE-1056 | B5: 100 | C5: 96 | D5: Inbound discrepancy | E5: Pallet count matches, but unit count does not match the packing list. | F5: =IF(OR(B5="",C5=""),"",C5-B5) -> -4 | G5: =IF(F5="","Pending Verification",IF(F5=0,"Matched",IF(F5<0,"Short Received","Over Received"))) -> Short Received | H5: =IF(F5="","",MAX(0,-F5)) -> 4 | I5: =IF(G5="Matched","No","Yes") -> Yes | J5: =IF(G5="Matched","No action required",IF(G5="Short Received","Hold PO closure - investigate shortage",IF(G5="Over Received","Investigate excess receipt","Verify missing data"))) -> Hold PO closure - investigate shortage | L5: =A5 -> PO-DE-1056 | M5: =B5 -> 100 | N5: =C5 -> 96 | T5: Matched POs
T7: =COUNTIF(G2:G5,"Matched") -> 2
T9: Short Received POs
T11: =COUNTIF(G2:G5,"Short Received") -> 2
T13: Over Received POs
T15: =COUNTIF(G2:G5,"Over Received") -> 0
T17: Total Shortage Units
T19: =SUM(H2:H5) -> 8

Sheet charts
A1: Warehouse | B1: Carrier | C1: Total Orders | D1: Shipped Orders | E1: Avg. Business Days | F1: Over SLA Orders | G1: Over SLA % | H1: Missing Ship Date Orders | J1: Warehouse | K1: Total Orders | L1: Shipped Orders | M1: Over SLA Orders | N1: Over SLA % | O1: Not Shipped Orders | P1: Avg. Business Days | R1: Category | S1: Within SLA | T1: Over SLA | U1: Missing Ship Date | W1: Warehouse | X1: Over SLA % | Y1: Over SLA / Shipped
A2: {=UNIQUE({'SLA Analysis'!D2:D61,'SLA Analysis'!F2:F61})} -> Fidelity NL | B2: FedEx | C2: =COUNTIFS('SLA Analysis'!D$2:D$61,A2,'SLA Analysis'!F$2:F$61,B2) -> 4 | D2: =COUNTIFS('SLA Analysis'!D$2:D$61,A2,'SLA Analysis'!F$2:F$61,B2,'SLA Analysis'!C$2:C$61,"<>") -> 4 | E2: =IFERROR(AVERAGEIFS('SLA Analysis'!I$2:I$61,'SLA Analysis'!D$2:D$61,A2,'SLA Analysis'!F$2:F$61,B2),"") -> 1.25 | F2: =COUNTIFS('SLA Analysis'!D$2:D$61,A2,'SLA Analysis'!F$2:F$61,B2,'SLA Analysis'!J$2:J$61,"Over SLA") -> 1 | G2: =IFERROR(F2/D2,0) -> 0.25 | H2: =COUNTIFS('SLA Analysis'!D$2:D$61,A2,'SLA Analysis'!F$2:F$61,B2,'SLA Analysis'!C$2:C$61,"") -> 0 | J2: {=UNIQUE(A2:A16)} -> Fidelity NL | K2: =SUMIF($A$2:$A$16,J2,$C$2:$C$16) -> 20 | L2: =SUMIF($A$2:$A$16,J2,$D$2:$D$16) -> 19 | M2: =SUMIF($A$2:$A$16,J2,$F$2:$F$16) -> 5 | N2: =IFERROR(M2/L2,0) -> 0.26315789 | O2: =SUMIF($A$2:$A$16,J2,$H$2:$H$16) -> 1 | P2: =IFERROR(AVERAGEIF('SLA Analysis'!$D$2:$D$61,J2,'SLA Analysis'!$I$2:$I$61),0) -> 1.7894737 | R2: All orders | S2: =COUNTIF('SLA Analysis'!J2:J61,S1) -> 37 | T2: =COUNTIF('SLA Analysis'!J2:J61,T1) -> 20 | U2: =COUNTIF('SLA Analysis'!J2:J61,U1) -> 3 | W2: Devlnd UK | X2: =INDEX($N$2:$N$4,MATCH(W2,$J$2:$J$4,0)) -> 0.47368421 | Y2: =INDEX($M$2:$M$4,MATCH(W2,$J$2:$J$4,0))&" / "&INDEX($L$2:$L$4,MATCH(W2,$J$2:$J$4,0)) -> 9 / 19
A3: Devlnd UK | B3: DPD | C3: =COUNTIFS('SLA Analysis'!D$2:D$61,A3,'SLA Analysis'!F$2:F$61,B3) -> 4 | D3: =COUNTIFS('SLA Analysis'!D$2:D$61,A3,'SLA Analysis'!F$2:F$61,B3,'SLA Analysis'!C$2:C$61,"<>") -> 4 | E3: =IFERROR(AVERAGEIFS('SLA Analysis'!I$2:I$61,'SLA Analysis'!D$2:D$61,A3,'SLA Analysis'!F$2:F$61,B3),"") -> 2.25 | F3: =COUNTIFS('SLA Analysis'!D$2:D$61,A3,'SLA Analysis'!F$2:F$61,B3,'SLA Analysis'!J$2:J$61,"Over SLA") -> 2 | G3: =IFERROR(F3/D3,0) -> 0.5 | H3: =COUNTIFS('SLA Analysis'!D$2:D$61,A3,'SLA Analysis'!F$2:F$61,B3,'SLA Analysis'!C$2:C$61,"") -> 0 | J3: Devlnd UK | K3: =SUMIF($A$2:$A$16,J3,$C$2:$C$16) -> 20 | L3: =SUMIF($A$2:$A$16,J3,$D$2:$D$16) -> 19 | M3: =SUMIF($A$2:$A$16,J3,$F$2:$F$16) -> 9 | N3: =IFERROR(M3/L3,0) -> 0.47368421 | O3: =SUMIF($A$2:$A$16,J3,$H$2:$H$16) -> 1 | P3: =IFERROR(AVERAGEIF('SLA Analysis'!$D$2:$D$61,J3,'SLA Analysis'!$I$2:$I$61),0) -> 2.4210526 | W3: InterFulfillment CA | X3: =INDEX($N$2:$N$4,MATCH(W3,$J$2:$J$4,0)) -> 0.31578947 | Y3: =INDEX($M$2:$M$4,MATCH(W3,$J$2:$J$4,0))&" / "&INDEX($L$2:$L$4,MATCH(W3,$J$2:$J$4,0)) -> 6 / 19
A4: InterFulfillment CA | B4: UPS | C4: =COUNTIFS('SLA Analysis'!D$2:D$61,A4,'SLA Analysis'!F$2:F$61,B4) -> 4 | D4: =COUNTIFS('SLA Analysis'!D$2:D$61,A4,'SLA Analysis'!F$2:F$61,B4,'SLA Analysis'!C$2:C$61,"<>") -> 4 | E4: =IFERROR(AVERAGEIFS('SLA Analysis'!I$2:I$61,'SLA Analysis'!D$2:D$61,A4,'SLA Analysis'!F$2:F$61,B4),"") -> 1.75 | F4: =COUNTIFS('SLA Analysis'!D$2:D$61,A4,'SLA Analysis'!F$2:F$61,B4,'SLA Analysis'!J$2:J$61,"Over SLA") -> 1 | G4: =IFERROR(F4/D4,0) -> 0.25 | H4: =COUNTIFS('SLA Analysis'!D$2:D$61,A4,'SLA Analysis'!F$2:F$61,B4,'SLA Analysis'!C$2:C$61,"") -> 0 | J4: InterFulfillment CA | K4: =SUMIF($A$2:$A$16,J4,$C$2:$C$16) -> 20 | L4: =SUMIF($A$2:$A$16,J4,$D$2:$D$16) -> 19 | M4: =SUMIF($A$2:$A$16,J4,$F$2:$F$16) -> 6 | N4: =IFERROR(M4/L4,0) -> 0.31578947 | O4: =SUMIF($A$2:$A$16,J4,$H$2:$H$16) -> 1 | P4: =IFERROR(AVERAGEIF('SLA Analysis'!$D$2:$D$61,J4,'SLA Analysis'!$I$2:$I$61),0) -> 1.8947368 | W4: Fidelity NL | X4: =INDEX($N$2:$N$4,MATCH(W4,$J$2:$J$4,0)) -> 0.26315789 | Y4: =INDEX($M$2:$M$4,MATCH(W4,$J$2:$J$4,0))&" / "&INDEX($L$2:$L$4,MATCH(W4,$J$2:$J$4,0)) -> 5 / 19
A5: Fidelity NL | B5: Royal Mail | C5: =COUNTIFS('SLA Analysis'!D$2:D$61,A5,'SLA Analysis'!F$2:F$61,B5) -> 4 | D5: =COUNTIFS('SLA Analysis'!D$2:D$61,A5,'SLA Analysis'!F$2:F$61,B5,'SLA Analysis'!C$2:C$61,"<>") -> 4 | E5: =IFERROR(AVERAGEIFS('SLA Analysis'!I$2:I$61,'SLA Analysis'!D$2:D$61,A5,'SLA Analysis'!F$2:F$61,B5),"") -> 1.5 | F5: =COUNTIFS('SLA Analysis'!D$2:D$61,A5,'SLA Analysis'!F$2:F$61,B5,'SLA Analysis'!J$2:J$61,"Over SLA") -> 1 | G5: =IFERROR(F5/D5,0) -> 0.25 | H5: =COUNTIFS('SLA Analysis'!D$2:D$61,A5,'SLA Analysis'!F$2:F$61,B5,'SLA Analysis'!C$2:C$61,"") -> 0
A6: Devlnd UK | B6: DHL | C6: =COUNTIFS('SLA Analysis'!D$2:D$61,A6,'SLA Analysis'!F$2:F$61,B6) -> 4 | D6: =COUNTIFS('SLA Analysis'!D$2:D$61,A6,'SLA Analysis'!F$2:F$61,B6,'SLA Analysis'!C$2:C$61,"<>") -> 4 | E6: =IFERROR(AVERAGEIFS('SLA Analysis'!I$2:I$61,'SLA Analysis'!D$2:D$61,A6,'SLA Analysis'!F$2:F$61,B6),"") -> 2.25 | F6: =COUNTIFS('SLA Analysis'!D$2:D$61,A6,'SLA Analysis'!F$2:F$61,B6,'SLA Analysis'!J$2:J$61,"Over SLA") -> 2 | G6: =IFERROR(F6/D6,0) -> 0.5 | H6: =COUNTIFS('SLA Analysis'!D$2:D$61,A6,'SLA Analysis'!F$2:F$61,B6,'SLA Analysis'!C$2:C$61,"") -> 0
A7: InterFulfillment CA | B7: FedEx | C7: =COUNTIFS('SLA Analysis'!D$2:D$61,A7,'SLA Analysis'!F$2:F$61,B7) -> 4 | D7: =COUNTIFS('SLA Analysis'!D$2:D$61,A7,'SLA Analysis'!F$2:F$61,B7,'SLA Analysis'!C$2:C$61,"<>") -> 4 | E7: =IFERROR(AVERAGEIFS('SLA Analysis'!I$2:I$61,'SLA Analysis'!D$2:D$61,A7,'SLA Analysis'!F$2:F$61,B7),"") -> 2.25 | F7: =COUNTIFS('SLA Analysis'!D$2:D$61,A7,'SLA Analysis'!F$2:F$61,B7,'SLA Analysis'!J$2:J$61,"Over SLA") -> 2 | G7: =IFERROR(F7/D7,0) -> 0.5 | H7: =COUNTIFS('SLA Analysis'!D$2:D$61,A7,'SLA Analysis'!F$2:F$61,B7,'SLA Analysis'!C$2:C$61,"") -> 0
A8: Fidelity NL | B8: DPD | C8: =COUNTIFS('SLA Analysis'!D$2:D$61,A8,'SLA Analysis'!F$2:F$61,B8) -> 4 | D8: =COUNTIFS('SLA Analysis'!D$2:D$61,A8,'SLA Analysis'!F$2:F$61,B8,'SLA Analysis'!C$2:C$61,"<>") -> 4 | E8: =IFERROR(AVERAGEIFS('SLA Analysis'!I$2:I$61,'SLA Analysis'!D$2:D$61,A8,'SLA Analysis'!F$2:F$61,B8),"") -> 2.5 | F8: =COUNTIFS('SLA Analysis'!D$2:D$61,A8,'SLA Analysis'!F$2:F$61,B8,'SLA Analysis'!J$2:J$61,"Over SLA") -> 2 | G8: =IFERROR(F8/D8,0) -> 0.5 | H8: =COUNTIFS('SLA Analysis'!D$2:D$61,A8,'SLA Analysis'!F$2:F$61,B8,'SLA Analysis'!C$2:C$61,"") -> 0
A9: Devlnd UK | B9: UPS | C9: =COUNTIFS('SLA Analysis'!D$2:D$61,A9,'SLA Analysis'!F$2:F$61,B9) -> 4 | D9: =COUNTIFS('SLA Analysis'!D$2:D$61,A9,'SLA Analysis'!F$2:F$61,B9,'SLA Analysis'!C$2:C$61,"<>") -> 4 | E9: =IFERROR(AVERAGEIFS('SLA Analysis'!I$2:I$61,'SLA Analysis'!D$2:D$61,A9,'SLA Analysis'!F$2:F$61,B9),"") -> 2.75 | F9: =COUNTIFS('SLA Analysis'!D$2:D$61,A9,'SLA Analysis'!F$2:F$61,B9,'SLA Analysis'!J$2:J$61,"Over SLA") -> 2 | G9: =IFERROR(F9/D9,0) -> 0.5 | H9: =COUNTIFS('SLA Analysis'!D$2:D$61,A9,'SLA Analysis'!F$2:F$61,B9,'SLA Analysis'!C$2:C$61,"") -> 0
A10: InterFulfillment CA | B10: Royal Mail | C10: =COUNTIFS('SLA Analysis'!D$2:D$61,A10,'SLA Analysis'!F$2:F$61,B10) -> 4 | D10: =COUNTIFS('SLA Analysis'!D$2:D$61,A10,'SLA Analysis'!F$2:F$61,B10,'SLA Analysis'!C$2:C$61,"<>") -> 4 | E10: =IFERROR(AVERAGEIFS('SLA Analysis'!I$2:I$61,'SLA Analysis'!D$2:D$61,A10,'SLA Analysis'!F$2:F$61,B10),"") -> 1.5 | F10: =COUNTIFS('SLA Analysis'!D$2:D$61,A10,'SLA Analysis'!F$2:F$61,B10,'SLA Analysis'!J$2:J$61,"Over SLA") -> 1 | G10: =IFERROR(F10/D10,0) -> 0.25 | H10: =COUNTIFS('SLA Analysis'!D$2:D$61,A10,'SLA Analysis'!F$2:F$61,B10,'SLA Analysis'!C$2:C$61,"") -> 0
A11: Fidelity NL | B11: DHL | C11: =COUNTIFS('SLA Analysis'!D$2:D$61,A11,'SLA Analysis'!F$2:F$61,B11) -> 4 | D11: =COUNTIFS('SLA Analysis'!D$2:D$61,A11,'SLA Analysis'!F$2:F$61,B11,'SLA Analysis'!C$2:C$61,"<>") -> 4 | E11: =IFERROR(AVERAGEIFS('SLA Analysis'!I$2:I$61,'SLA Analysis'!D$2:D$61,A11,'SLA Analysis'!F$2:F$61,B11),"") -> 2 | F11: =COUNTIFS('SLA Analysis'!D$2:D$61,A11,'SLA Analysis'!F$2:F$61,B11,'SLA Analysis'!J$2:J$61,"Over SLA") -> 1 | G11: =IFERROR(F11/D11,0) -> 0.25 | H11: =COUNTIFS('SLA Analysis'!D$2:D$61,A11,'SLA Analysis'!F$2:F$61,B11,'SLA Analysis'!C$2:C$61,"") -> 0
A12: Devlnd UK | B12: FedEx | C12: =COUNTIFS('SLA Analysis'!D$2:D$61,A12,'SLA Analysis'!F$2:F$61,B12) -> 4 | D12: =COUNTIFS('SLA Analysis'!D$2:D$61,A12,'SLA Analysis'!F$2:F$61,B12,'SLA Analysis'!C$2:C$61,"<>") -> 3 | E12: =IFERROR(AVERAGEIFS('SLA Analysis'!I$2:I$61,'SLA Analysis'!D$2:D$61,A12,'SLA Analysis'!F$2:F$61,B12),"") -> 2 | F12: =COUNTIFS('SLA Analysis'!D$2:D$61,A12,'SLA Analysis'!F$2:F$61,B12,'SLA Analysis'!J$2:J$61,"Over SLA") -> 1 | G12: =IFERROR(F12/D12,0) -> 0.33333333 | H12: =COUNTIFS('SLA Analysis'!D$2:D$61,A12,'SLA Analysis'!F$2:F$61,B12,'SLA Analysis'!C$2:C$61,"") -> 1
A13: InterFulfillment CA | B13: DPD | C13: =COUNTIFS('SLA Analysis'!D$2:D$61,A13,'SLA Analysis'!F$2:F$61,B13) -> 4 | D13: =COUNTIFS('SLA Analysis'!D$2:D$61,A13,'SLA Analysis'!F$2:F$61,B13,'SLA Analysis'!C$2:C$61,"<>") -> 3 | E13: =IFERROR(AVERAGEIFS('SLA Analysis'!I$2:I$61,'SLA Analysis'!D$2:D$61,A13,'SLA Analysis'!F$2:F$61,B13),"") -> 2.3333333 | F13: =COUNTIFS('SLA Analysis'!D$2:D$61,A13,'SLA Analysis'!F$2:F$61,B13,'SLA Analysis'!J$2:J$61,"Over SLA") -> 1 | G13: =IFERROR(F13/D13,0) -> 0.33333333 | H13: =COUNTIFS('SLA Analysis'!D$2:D$61,A13,'SLA Analysis'!F$2:F$61,B13,'SLA Analysis'!C$2:C$61,"") -> 1
A14: Fidelity NL | B14: UPS | C14: =COUNTIFS('SLA Analysis'!D$2:D$61,A14,'SLA Analysis'!F$2:F$61,B14) -> 4 | D14: =COUNTIFS('SLA Analysis'!D$2:D$61,A14,'SLA Analysis'!F$2:F$61,B14,'SLA Analysis'!C$2:C$61,"<>") -> 3 | E14: =IFERROR(AVERAGEIFS('SLA Analysis'!I$2:I$61,'SLA Analysis'!D$2:D$61,A14,'SLA Analysis'!F$2:F$61,B14),"") -> 1.6666667 | F14: =COUNTIFS('SLA Analysis'!D$2:D$61,A14,'SLA Analysis'!F$2:F$61,B14,'SLA Analysis'!J$2:J$61,"Over SLA") -> 0 | G14: =IFERROR(F14/D14,0) -> 0 | H14: =COUNTIFS('SLA Analysis'!D$2:D$61,A14,'SLA Analysis'!F$2:F$61,B14,'SLA Analysis'!C$2:C$61,"") -> 1
A15: Devlnd UK | B15: Royal Mail | C15: =COUNTIFS('SLA Analysis'!D$2:D$61,A15,'SLA Analysis'!F$2:F$61,B15) -> 4 | D15: =COUNTIFS('SLA Analysis'!D$2:D$61,A15,'SLA Analysis'!F$2:F$61,B15,'SLA Analysis'!C$2:C$61,"<>") -> 4 | E15: =IFERROR(AVERAGEIFS('SLA Analysis'!I$2:I$61,'SLA Analysis'!D$2:D$61,A15,'SLA Analysis'!F$2:F$61,B15),"") -> 2.75 | F15: =COUNTIFS('SLA Analysis'!D$2:D$61,A15,'SLA Analysis'!F$2:F$61,B15,'SLA Analysis'!J$2:J$61,"Over SLA") -> 2 | G15: =IFERROR(F15/D15,0) -> 0.5 | H15: =COUNTIFS('SLA Analysis'!D$2:D$61,A15,'SLA Analysis'!F$2:F$61,B15,'SLA Analysis'!C$2:C$61,"") -> 0
A16: InterFulfillment CA | B16: DHL | C16: =COUNTIFS('SLA Analysis'!D$2:D$61,A16,'SLA Analysis'!F$2:F$61,B16) -> 4 | D16: =COUNTIFS('SLA Analysis'!D$2:D$61,A16,'SLA Analysis'!F$2:F$61,B16,'SLA Analysis'!C$2:C$61,"<>") -> 4 | E16: =IFERROR(AVERAGEIFS('SLA Analysis'!I$2:I$61,'SLA Analysis'!D$2:D$61,A16,'SLA Analysis'!F$2:F$61,B16),"") -> 1.75 | F16: =COUNTIFS('SLA Analysis'!D$2:D$61,A16,'SLA Analysis'!F$2:F$61,B16,'SLA Analysis'!J$2:J$61,"Over SLA") -> 1 | G16: =IFERROR(F16/D16,0) -> 0.25 | H16: =COUNTIFS('SLA Analysis'!D$2:D$61,A16,'SLA Analysis'!F$2:F$61,B16,'SLA Analysis'!C$2:C$61,"") -> 0
